Workbook

Sheet Summary
A1: Word | B1: Guesses | C1: Correct | D1: Accuracy | E1: Avg confidence (all guesses) | F1: Avg confidence (correct only) | G1: Guesses at 80%+ | H1: Guesses under 60% | I1: Avg loudness
A2: marvin | B2: =COUNTIF('Guess Log'!$C$2:$C$170,A2) -> 23 | C2: =COUNTIFS('Guess Log'!$C$2:$C$170,A2,'Guess Log'!$G$2:$G$170,"Yes") -> 23 | D2: =IF(B2=0,0,C2/B2) -> 1 | E2: =AVERAGEIF('Guess Log'!$C$2:$C$170,A2,'Guess Log'!$E$2:$E$170) -> 0.86043478 | F2: =AVERAGEIFS('Guess Log'!$E$2:$E$170,'Guess Log'!$C$2:$C$170,A2,'Guess Log'!$G$2:$G$170,"Yes") -> 0.86043478 | G2: =COUNTIFS('Guess Log'!$C$2:$C$170,A2,'Guess Log'!$D$2:$D$170,A2,'Guess Log'!$E$2:$E$170,">=0.8") -> 19 | H2: =COUNTIFS('Guess Log'!$C$2:$C$170,A2,'Guess Log'!$D$2:$D$170,A2,'Guess Log'!$E$2:$E$170,"<0.6") -> 2 | I2: =AVERAGEIF('Guess Log'!$C$2:$C$170,A2,'Guess Log'!$F$2:$F$170) -> 0.036521739
A3: yes | B3: =COUNTIF('Guess Log'!$C$2:$C$170,A3) -> 24 | C3: =COUNTIFS('Guess Log'!$C$2:$C$170,A3,'Guess Log'!$G$2:$G$170,"Yes") -> 23 | D3: =IF(B3=0,0,C3/B3) -> 0.95833333 | E3: =AVERAGEIF('Guess Log'!$C$2:$C$170,A3,'Guess Log'!$E$2:$E$170) -> 0.77 | F3: =AVERAGEIFS('Guess Log'!$E$2:$E$170,'Guess Log'!$C$2:$C$170,A3,'Guess Log'!$G$2:$G$170,"Yes") -> 0.79043478 | G3: =COUNTIFS('Guess Log'!$C$2:$C$170,A3,'Guess Log'!$D$2:$D$170,A3,'Guess Log'!$E$2:$E$170,">=0.8") -> 14 | H3: =COUNTIFS('Guess Log'!$C$2:$C$170,A3,'Guess Log'!$D$2:$D$170,A3,'Guess Log'!$E$2:$E$170,"<0.6") -> 5 | I3: =AVERAGEIF('Guess Log'!$C$2:$C$170,A3,'Guess Log'!$F$2:$F$170) -> 0.053333333
A4: no | B4: =COUNTIF('Guess Log'!$C$2:$C$170,A4) -> 24 | C4: =COUNTIFS('Guess Log'!$C$2:$C$170,A4,'Guess Log'!$G$2:$G$170,"Yes") -> 23 | D4: =IF(B4=0,0,C4/B4) -> 0.95833333 | E4: =AVERAGEIF('Guess Log'!$C$2:$C$170,A4,'Guess Log'!$E$2:$E$170) -> 0.86625 | F4: =AVERAGEIFS('Guess Log'!$E$2:$E$170,'Guess Log'!$C$2:$C$170,A4,'Guess Log'!$G$2:$G$170,"Yes") -> 0.89086957 | G4: =COUNTIFS('Guess Log'!$C$2:$C$170,A4,'Guess Log'!$D$2:$D$170,A4,'Guess Log'!$E$2:$E$170,">=0.8") -> 19 | H4: =COUNTIFS('Guess Log'!$C$2:$C$170,A4,'Guess Log'!$D$2:$D$170,A4,'Guess Log'!$E$2:$E$170,"<0.6") -> 2 | I4: =AVERAGEIF('Guess Log'!$C$2:$C$170,A4,'Guess Log'!$F$2:$F$170) -> 0.05875
A5: go | B5: =COUNTIF('Guess Log'!$C$2:$C$170,A5) -> 27 | C5: =COUNTIFS('Guess Log'!$C$2:$C$170,A5,'Guess Log'!$G$2:$G$170,"Yes") -> 26 | D5: =IF(B5=0,0,C5/B5) -> 0.96296296 | E5: =AVERAGEIF('Guess Log'!$C$2:$C$170,A5,'Guess Log'!$E$2:$E$170) -> 0.85777778 | F5: =AVERAGEIFS('Guess Log'!$E$2:$E$170,'Guess Log'!$C$2:$C$170,A5,'Guess Log'!$G$2:$G$170,"Yes") -> 0.88153846 | G5: =COUNTIFS('Guess Log'!$C$2:$C$170,A5,'Guess Log'!$D$2:$D$170,A5,'Guess Log'!$E$2:$E$170,">=0.8") -> 22 | H5: =COUNTIFS('Guess Log'!$C$2:$C$170,A5,'Guess Log'!$D$2:$D$170,A5,'Guess Log'!$E$2:$E$170,"<0.6") -> 2 | I5: =AVERAGEIF('Guess Log'!$C$2:$C$170,A5,'Guess Log'!$F$2:$F$170) -> 0.065555556
A6: stop | B6: =COUNTIF('Guess Log'!$C$2:$C$170,A6) -> 42 | C6: =COUNTIFS('Guess Log'!$C$2:$C$170,A6,'Guess Log'!$G$2:$G$170,"Yes") -> 40 | D6: =IF(B6=0,0,C6/B6) -> 0.95238095 | E6: =AVERAGEIF('Guess Log'!$C$2:$C$170,A6,'Guess Log'!$E$2:$E$170) -> 0.7252381 | F6: =AVERAGEIFS('Guess Log'!$E$2:$E$170,'Guess Log'!$C$2:$C$170,A6,'Guess Log'!$G$2:$G$170,"Yes") -> 0.73825 | G6: =COUNTIFS('Guess Log'!$C$2:$C$170,A6,'Guess Log'!$D$2:$D$170,A6,'Guess Log'!$E$2:$E$170,">=0.8") -> 18 | H6: =COUNTIFS('Guess Log'!$C$2:$C$170,A6,'Guess Log'!$D$2:$D$170,A6,'Guess Log'!$E$2:$E$170,"<0.6") -> 13 | I6: =AVERAGEIF('Guess Log'!$C$2:$C$170,A6,'Guess Log'!$F$2:$F$170) -> 0.060238095
A7: All words | B7: =SUM(B2:B6) -> 140 | C7: =SUM(C2:C6) -> 135 | D7: =IF(B7=0,0,C7/B7) -> 0.96428571 | E7: =AVERAGEIFS('Guess Log'!$E$2:$E$170,'Guess Log'!$C$2:$C$170,"<>idle") -> 0.80485714 | F7: =AVERAGEIFS('Guess Log'!$E$2:$E$170,'Guess Log'!$G$2:$G$170,"Yes") -> 0.82155556 | G7: =SUM(G2:G6) -> 92 | H7: =SUM(H2:H6) -> 24 | I7: =AVERAGEIFS('Guess Log'!$F$2:$F$170,'Guess Log'!$C$2:$C$170,"<>idle") -> 0.055928571
A9: Idle (no talking) | B9: =COUNTIF('Guess Log'!$C$2:$C$170,"idle") -> 29 | E9: =AVERAGEIF('Guess Log'!$C$2:$C$170,"idle",'Guess Log'!$E$2:$E$170) -> 0.26655172 | I9: =AVERAGEIF('Guess Log'!$C$2:$C$170,"idle",'Guess Log'!$F$2:$F$170) -> 0.021034483
A11: Wake-ups | B11: =COUNTIF('Guess Log'!$H$2:$H$170,"Woke up*") -> 5
A12: Commands carried out | B12: 0
A14: Notes
A15: Source: Arduino IDE Serial Monitor log from Luke's Marvin test on 10/16/2026 (Nano 33 BLE, COM5, 115200 baud, debug on).
A16: "Word being tested" is the word you were saying at the time. Guesses at a switch between words count toward the next word.
A17: "Correct only" averages leave out guesses where Marvin picked the wrong word.
A18: Commands carried out is 0 because yes/no/go/stop were tested without saying "marvin" first. These rows show accuracy only.

Sheet Guess Log
A1: # | B1: Debug session | C1: Word being tested | D1: Marvin heard | E1: Confidence | F1: Loudness | G1: Correct? | H1: Note
A2: 1 | B2: 1 | C2: idle | D2: marvin | E2: 0.29 | F2: 0.02 | G2: =IF(C2="idle","n/a",IF(C2=D2,"Yes","No")) -> n/a
A3: 2 | B3: 1 | C3: idle | D3: marvin | E3: 0.26 | F3: 0.02 | G3: =IF(C3="idle","n/a",IF(C3=D3,"Yes","No")) -> n/a
A4: 3 | B4: 1 | C4: idle | D4: marvin | E4: 0.3 | F4: 0.02 | G4: =IF(C4="idle","n/a",IF(C4=D4,"Yes","No")) -> n/a
A5: 4 | B5: 1 | C5: idle | D5: marvin | E5: 0.26 | F5: 0.02 | G5: =IF(C5="idle","n/a",IF(C5=D5,"Yes","No")) -> n/a
A6: 5 | B6: 1 | C6: idle | D6: marvin | E6: 0.26 | F6: 0.02 | G6: =IF(C6="idle","n/a",IF(C6=D6,"Yes","No")) -> n/a
A7: 6 | B7: 1 | C7: idle | D7: marvin | E7: 0.26 | F7: 0.02 | G7: =IF(C7="idle","n/a",IF(C7=D7,"Yes","No")) -> n/a
A8: 7 | B8: 1 | C8: idle | D8: marvin | E8: 0.3 | F8: 0.02 | G8: =IF(C8="idle","n/a",IF(C8=D8,"Yes","No")) -> n/a
A9: 8 | B9: 1 | C9: idle | D9: marvin | E9: 0.26 | F9: 0.02 | G9: =IF(C9="idle","n/a",IF(C9=D9,"Yes","No")) -> n/a
A10: 9 | B10: 1 | C10: idle | D10: marvin | E10: 0.25 | F10: 0.02 | G10: =IF(C10="idle","n/a",IF(C10=D10,"Yes","No")) -> n/a
A11: 10 | B11: 1 | C11: idle | D11: marvin | E11: 0.23 | F11: 0.02 | G11: =IF(C11="idle","n/a",IF(C11=D11,"Yes","No")) -> n/a
A12: 11 | B12: 1 | C12: idle | D12: marvin | E12: 0.29 | F12: 0.02 | G12: =IF(C12="idle","n/a",IF(C12=D12,"Yes","No")) -> n/a
A13: 12 | B13: 1 | C13: idle | D13: marvin | E13: 0.23 | F13: 0.02 | G13: =IF(C13="idle","n/a",IF(C13=D13,"Yes","No")) -> n/a
... A29: 28 | B29: 2 | C29: idle | D29: marvin | E29: 0.29 | F29: 0.02 | G29: =IF(C29="idle","n/a",IF(C29=D29,"Yes","No")) -> n/a
A30: 29 | B30: 2 | C30: marvin | D30: marvin | E30: 0.91 | F30: 0.04 | G30: =IF(C30="idle","n/a",IF(C30=D30,"Yes","No")) -> Yes | H30: Woke up: "Heard my name (60%)" at 257.94 s
A31: 30 | B31: 2 | C31: marvin | D31: marvin | E31: 0.94 | F31: 0.04 | G31: =IF(C31="idle","n/a",IF(C31=D31,"Yes","No")) -> Yes
A32: 31 | B32: 2 | C32: marvin | D32: marvin | E32: 0.96 | F32: 0.03 | G32: =IF(C32="idle","n/a",IF(C32=D32,"Yes","No")) -> Yes
A33: 32 | B33: 2 | C33: marvin | D33: marvin | E33: 0.96 | F33: 0.04 | G33: =IF(C33="idle","n/a",IF(C33=D33,"Yes","No")) -> Yes
A34: 33 | B34: 2 | C34: marvin | D34: marvin | E34: 0.91 | F34: 0.03 | G34: =IF(C34="idle","n/a",IF(C34=D34,"Yes","No")) -> Yes | H34: No command heard, back to sleep (261.00 s)
A35: 34 | B35: 2 | C35: marvin | D35: marvin | E35: 0.95 | F35: 0.04 | G35: =IF(C35="idle","n/a",IF(C35=D35,"Yes","No")) -> Yes | H35: Woke up: "Heard my name (93%)" at 261.77 s
A36: 35 | B36: 2 | C36: marvin | D36: marvin | E36: 0.94 | F36: 0.04 | G36: =IF(C36="idle","n/a",IF(C36=D36,"Yes","No")) -> Yes
A37: 36 | B37: 2 | C37: marvin | D37: marvin | E37: 0.97 | F37: 0.04 | G37: =IF(C37="idle","n/a",IF(C37=D37,"Yes","No")) -> Yes
A38: 37 | B38: 2 | C38: marvin | D38: marvin | E38: 0.82 | F38: 0.03 | G38: =IF(C38="idle","n/a",IF(C38=D38,"Yes","No")) -> Yes
A39: 38 | B39: 2 | C39: marvin | D39: marvin | E39: 0.85 | F39: 0.04 | G39: =IF(C39="idle","n/a",IF(C39=D39,"Yes","No")) -> Yes | H39: No command heard, back to sleep (264.83 s)
A40: 39 | B40: 2 | C40: marvin | D40: marvin | E40: 0.75 | F40: 0.04 | G40: =IF(C40="idle","n/a",IF(C40=D40,"Yes","No")) -> Yes | H40: Woke up: "Heard my name (80%)" at 265.59 s
A41: 40 | B41: 2 | C41: marvin | D41: marvin | E41: 0.82 | F41: 0.03 | G41: =IF(C41="idle","n/a",IF(C41=D41,"Yes","No")) -> Yes
A42: 41 | B42: 2 | C42: marvin | D42: marvin | E42: 0.89 | F42: 0.05 | G42: =IF(C42="idle","n/a",IF(C42=D42,"Yes","No")) -> Yes
A43: 42 | B43: 2 | C43: marvin | D43: marvin | E43: 0.96 | F43: 0.04 | G43: =IF(C43="idle","n/a",IF(C43=D43,"Yes","No")) -> Yes
A44: 43 | B44: 2 | C44: marvin | D44: marvin | E44: 0.97 | F44: 0.04 | G44: =IF(C44="idle","n/a",IF(C44=D44,"Yes","No")) -> Yes | H44: No command heard, back to sleep (268.65 s)
A45: 44 | B45: 2 | C45: marvin | D45: marvin | E45: 0.85 | F45: 0.04 | G45: =IF(C45="idle","n/a",IF(C45=D45,"Yes","No")) -> Yes | H45: Woke up: "Heard my name (91%)" at 269.42 s
A46: 45 | B46: 2 | C46: marvin | D46: marvin | E46: 0.97 | F46: 0.05 | G46: =IF(C46="idle","n/a",IF(C46=D46,"Yes","No")) -> Yes
A47: 46 | B47: 2 | C47: marvin | D47: marvin | E47: 0.95 | F47: 0.03 | G47: =IF(C47="idle","n/a",IF(C47=D47,"Yes","No")) -> Yes
A48: 47 | B48: 2 | C48: marvin | D48: marvin | E48: 0.74 | F48: 0.03 | G48: =IF(C48="idle","n/a",IF(C48=D48,"Yes","No")) -> Yes
A49: 48 | B49: 2 | C49: marvin | D49: marvin | E49: 0.89 | F49: 0.04 | G49: =IF(C49="idle","n/a",IF(C49=D49,"Yes","No")) -> Yes | H49: No command heard, back to sleep (272.48 s)
A50: 49 | B50: 2 | C50: marvin | D50: marvin | E50: 0.96 | F50: 0.04 | G50: =IF(C50="idle","n/a",IF(C50=D50,"Yes","No")) -> Yes | H50: Woke up: "Heard my name (93%)" at 273.25 s
A51: 50 | B51: 2 | C51: marvin | D51: marvin | E51: 0.57 | F51: 0.02 | G51: =IF(C51="idle","n/a",IF(C51=D51,"Yes","No")) -> Yes
A52: 51 | B52: 2 | C52: marvin | D52: marvin | E52: 0.26 | F52: 0.02 | G52: =IF(C52="idle","n/a",IF(C52=D52,"Yes","No")) -> Yes
A53: 52 | B53: 2 | C53: idle | D53: silence | E53: 0.27 | F53: 0.05 | G53: =IF(C53="idle","n/a",IF(C53=D53,"Yes","No")) -> n/a | H53: Not talking here (Luke confirmed)
A54: 53 | B54: 2 | C54: yes | D54: yes | E54: 0.98 | F54: 0.06 | G54: =IF(C54="idle","n/a",IF(C54=D54,"Yes","No")) -> Yes | H54: No command heard, back to sleep (276.31 s)
A55: 54 | B55: 2 | C55: yes | D55: yes | E55: 0.88 | F55: 0.06 | G55: =IF(C55="idle","n/a",IF(C55=D55,"Yes","No")) -> Yes
...
